Workbook
Name JobIDs: Jobs!$A$5:$A$44
Name ClientNames: Clients!$A$5:$A$104
Name CostCodes: Settings!$E$5:$E$28
Name CrewNames: 'Vendors & Crew'!$A$5:$A$34
Name VendorNames: 'Vendors & Crew'!$A$41:$A$140
Name InvoiceNumbers: Invoices!$A$5:$A$204
Name LibraryItems: 'Cost Library'!$A$5:$A$204
Name MarkupTable: Settings!$A$22:$B$27

Sheet Start Here
B1: Contractor Job Costing & Estimate Spreadsheet
B3: Estimate → schedule → track hours and costs → change orders → invoice → collect → see real profit. Works in Microsoft Excel (2016+, 365, Mac) and Google Sheets. Version 1.0 (2026-09).
B5: HOW IT FLOWS
B6: 1 Settings | C6: 2 Clients, Vendors & Crew | D6: 3 Jobs | E6: 4 Estimate → Proposal | F6: 5 Schedule | G6: 6 Timesheet, Costs, Mileage, Log | H6: 7 Change Orders | I6: 8 Invoices → Payments
B7: Dashboard, Job Profit Report, Reports, Tax Summary and Health Check update themselves from these inputs.
B9: SETUP
B10: Settings | C10: Company details, markups, tax, deposit and progress %, mileage rate, labor burden, cost codes, document text. Start here.
B11: Clients | C11: Client directory with lifetime value and balance due.
B12: Vendors & Crew | C12: Crew rates for the Timesheet; vendor and sub directory with insurance alerts and 1099 flags.
B13: Cost Library | C13: Your price book: items with unit and unit cost that fill into estimates.
B15: INPUTS
B16: Jobs | C16: One row per job. Everything rolls up here.
B17: Estimate | C17: Line-by-line quote with automatic category markup and library lookups.
B18: Schedule | C18: Tasks with workday end dates and a 12-week Gantt chart.
B19: Timesheet | C19: Crew hours by day and job with a weekly payroll summary.
B20: Job Costs | C20: Materials, subs, equipment, permits and other actual costs.
B21: Mileage | C21: Job-related driving at your mileage rate.
B22: Daily Log | C22: Weather, crew, work performed, issues, inspections — your dispute record.
B23: Change Orders | C23: Added work; approved COs raise the contract and the budget.
B24: Invoices | C24: Invoices with balances, status, days overdue and aging bucket.
B25: Payments | C25: Money received, linked to invoices and jobs.
B27: DOCUMENTS & REPORTS
B28: Proposal | C28: Client-ready proposal: scope, payment schedule, detailed lines, terms, signatures.
B29: CO Form | C29: Signature-ready change order document.
B30: Invoice Print | C30: Printable invoice with contract summary.
B31: Client Statement | C31: All of a client's invoices, balances and aging on one page.
B32: Job Profit Report | C32: Budget vs actual by category and cost code for one job.
B33: Reports | C33: Receivables aging, cash forecast, pipeline, win rate, cost-code performance.
B34: Tax Summary | C34: Year-end totals by category, mileage, 1099 review list.
B35: Dashboard | C35: 16 KPIs, alerts, charts, per-job table, monthly P&L.
B36: Health Check | C36: Counts data problems and formula errors. Keep it at ALL CLEAR.
B38: TEN-MINUTE SETUP
B39: 1. Settings: company details, markups, contingency, tax, deposit %, mileage rate, labor burden. Rename cost codes to match your trade.
B40: 2. Vendors & Crew: add your workers with cost and bill rates, and your subs and suppliers.
B41: 3. Clients and Jobs: add a client, then a job row with a Job ID such as J-1001 (the sheet suggests the next one).
B42: 4. Estimate the job, open Proposal, pick the Job ID, print. Enter the signed Contract Value on Jobs.
B43: 5. As work happens: Timesheet for crew hours, Job Costs for everything else, Mileage, Daily Log, Change Orders.
B44: 6. Invoice from the Invoices sheet and print with Invoice Print; record Payments; send Client Statements. Watch the Dashboard.
B46: COLOR KEY
B47: Light-blue cells are inputs. Every other cell is a formula: do not type over them (Undo with Ctrl+Z / Cmd+Z if you do).
...

Sheet Dashboard
A1: Dashboard
A2: Company-wide view. Everything here is calculated. Change the reporting year in Settings to move the monthly P&L. | K2: As of | L2: =TODAY()
B4: Revised contract value (all jobs) | E4: Estimated cost | H4: Actual cost to date | K4: Projected gross profit
B5: =Jobs!K45 | E5: =Jobs!L45 | H5: =Jobs!M45 | K5: =Jobs!T45
B7: Projected gross margin | E7: Margin after overhead (Settings %) | H7: Invoiced | K7: Collected
B8: =Jobs!U45 | E8: =IF(Jobs!K45=0,0,(Jobs!T45-Jobs!K45*Settings!$B$17)/Jobs!K45) | H8: =Jobs!Q45 | K8: =Jobs!R45
B10: Outstanding balance | E10: Overdue balance | H10: Backlog (active jobs not yet invoiced) | K10: Unpaid bills logged (Paid? = No)
B11: =Jobs!S45 | E11: =SUMIFS(Invoices!$H$5:$H$204,Invoices!$I$5:$I$204,"Overdue") | H11: =SUMIFS(Jobs!$K$5:$K$44,Jobs!$D$5:$D$44,"Approved")+SUMIFS(Jobs!$K$5:$K$44,Jobs!$D$5:$D$44,"In Progress")-(SUMIFS(Jobs!$Q$5:$Q$44,Jobs!$D$5:$D$44,"Approved")+SUMIFS(Jobs!$Q$5:$Q$44,Jobs!$D$5:$D$44,"In Progress")) | K11: =SUMIFS('Job Costs'!$I$5:$I$1004,'Job Costs'!$J$5:$J$1004,"No")
B13: Active jobs (Approved / In Progress) | E13: Jobs over budget | H13: Labor hours this month | K13: Win rate (won ÷ won + lost)
B14: =COUNTIF(Jobs!$D$5:$D$44,"Approved")+COUNTIF(Jobs!$D$5:$D$44,"In Progress") | E14: =COUNTIF(Jobs!$O$5:$O$44,">1") | H14: =SUMIFS(Timesheet!$E$5:$E$1004,Timesheet!$A$5:$A$1004,">="&DATE(YEAR(TODAY()),MONTH(TODAY()),1),Timesheet!$A$5:$A$1004,"<="&EOMONTH(TODAY(),0)) | K14: =IF(COUNTIF(Jobs!$D$5:$D$44,"Approved")+COUNTIF(Jobs!$D$5:$D$44,"In Progress")+COUNTIF(Jobs!$D$5:$D$44,"Complete")+COUNTIF(Jobs!$D$5:$D$44,"Closed")+COUNTIF(Jobs!$D$5:$D$44,"Lost")=0,0,(COUNTIF(Jobs!$D$5:$D$44,"Approved")+COUNTIF(Jobs!$D$5:$D$44,"In Progress")+COUNTIF(Jobs!$D$5:$D$44,"Complete")+COUNTIF(Jobs!$D$5:$D$44,"Closed"))/(COUNTIF(Jobs!$D$5:$D$44,"Approved")+COUNTIF(Jobs!$D$5:$D$44,"In Progress")+COUNTIF(Jobs!$D$5:$D$44,"Complete")+COUNTIF(Jobs!$D$5:$D$44,"Closed")+COUNTIF(Jobs!$D$5:$D$44,"Lost")))
B16: ALERTS
B17: Overdue invoices | E17: Late schedule tasks | H17: Vendor insurance expired / expiring | K17: Data issues (Health Check)
B18: =COUNTIF(Invoices!$I$5:$I$204,"Overdue") | E18: =COUNTIF(Schedule!$H$5:$H$204,"Late") | H18: =COUNTIF('Vendors & Crew'!$H$41:$H$140,"EXPIRED")+COUNTIF('Vendors & Crew'!$H$41:$H$140,"Expiring soon") | K18: ='Health Check'!C19
B20: THIS MONTH
B21: Invoiced this month | E21: Collected this month | H21: Costs this month (all sources) | K21: Cash profit this month
B22: =SUMIFS(Invoices!$E$5:$E$204,Invoices!$C$5:$C$204,">="&DATE(YEAR(TODAY()),MONTH(TODAY()),1),Invoices!$C$5:$C$204,"<="&EOMONTH(TODAY(),0)) | E22: =SUMIFS(Payments!$D$5:$D$304,Payments!$A$5:$A$304,">="&DATE(YEAR(TODAY()),MONTH(TODAY()),1),Payments!$A$5:$A$304,"<="&EOMONTH(TODAY(),0)) | H22: =SUMIFS('Job Costs'!$I$5:$I$1004,'Job Costs'!$A$5:$A$1004,">="&DATE(YEAR(TODAY()),MONTH(TODAY()),1),'Job Costs'!$A$5:$A$1004,"<="&EOMONTH(TODAY(),0))+SUMIFS(Timesheet!$H$5:$H$1004,Timesheet!$A$5:$A$1004,">="&DATE(YEAR(TODAY()),MONTH(TODAY()),1),Timesheet!$A$5:$A$1004,"<="&EOMONTH(TODAY(),0))+SUMIFS(Mileage!$I$5:$I$304,Mileage!$A$5:$A$304,">="&DATE(YEAR(TODAY()),MONTH(TODAY()),1),Mileage!$A$5:$A$304,"<="&EOMONTH(TODAY(),0)) | K22: =E22-H22
B24: Charts
B39: Jobs
B40: Job ID | C40: Client | D40: Status | E40: Revised Contract | F40: Actual Cost | G40: Projected Profit | H40: Margin % | I40: % Budget Used | J40: Balance Due | K40: Days to Target | L40: Hours
B41: =IF(Jobs!$A5="","",Jobs!A5) | C41: =IF(Jobs!$A5="","",Jobs!B5) | D41: =IF(Jobs!$A5="","",Jobs!D5) | E41: =IF(Jobs!$A5="","",Jobs!K5) | F41: =IF(Jobs!$A5="","",Jobs!M5) | G41: =IF(Jobs!$A5="","",Jobs!T5) | H41: =IF(Jobs!$A5="","",Jobs!U5) | I41: =IF(Jobs!$A5="","",Jobs!O5) | J41: =IF(Jobs!$A5="","",Jobs!S5) | K41: =IF(Jobs!$A5="","",Jobs!W5) | L41: =IF(Jobs!$A5="","",Jobs!P5)
B42: =IF(Jobs!$A6="","",Jobs!A6) | C42: =IF(Jobs!$A6="","",Jobs!B6) | D42: =IF(Jobs!$A6="","",Jobs!D6) | E42: =IF(Jobs!$A6="","",Jobs!K6) | F42: =IF(Jobs!$A6="","",Jobs!M6) | G42: =IF(Jobs!$A6="","",Jobs!T6) | H42: =IF(Jobs!$A6="","",Jobs!U6) | I42: =IF(Jobs!$A6="","",Jobs!O6) | J42: =IF(Jobs!$A6="","",Jobs!S6) | K42: =IF(Jobs!$A6="","",Jobs!W6) | L42: =IF(Jobs!$A6="","",Jobs!P6)
B43: =IF(Jobs!$A7="","",Jobs!A7) | C43: =IF(Jobs!$A7="","",Jobs!B7) | D43: =IF(Jobs!$A7="","",Jobs!D7) | E43: =IF(Jobs!$A7="","",Jobs!K7) | F43: =IF(Jobs!$A7="","",Jobs!M7) | G43: =IF(Jobs!$A7="","",Jobs!T7) | H43: =IF(Jobs!$A7="","",Jobs!U7) | I43: =IF(Jobs!$A7="","",Jobs!O7) | J43: =IF(Jobs!$A7="","",Jobs!S7) | K43: =IF(Jobs!$A7="","",Jobs!W7) | L43: =IF(Jobs!$A7="","",Jobs!P7)
B44: =IF(Jobs!$A8="","",Jobs!A8) | C44: =IF(Jobs!$A8="","",Jobs!B8) | D44: =IF(Jobs!$A8="","",Jobs!D8) | E44: =IF(Jobs!$A8="","",Jobs!K8) | F44: =IF(Jobs!$A8="","",Jobs!M8) | G44: =IF(Jobs!$A8="","",Jobs!T8) | H44: =IF(Jobs!$A8="","",Jobs!U8) | I44: =IF(Jobs!$A8="","",Jobs!O8) | J44: =IF(Jobs!$A8="","",Jobs!S8) | K44: =IF(Jobs!$A8="","",Jobs!W8) | L44: =IF(Jobs!$A8="","",Jobs!P8)
B45: =IF(Jobs!$A9="","",Jobs!A9) | C45: =IF(Jobs!$A9="","",Jobs!B9) | D45: =IF(Jobs!$A9="","",Jobs!D9) | E45: =IF(Jobs!$A9="","",Jobs!K9) | F45: =IF(Jobs!$A9="","",Jobs!M9) | G45: =IF(Jobs!$A9="","",Jobs!T9) | H45: =IF(Jobs!$A9="","",Jobs!U9) | I45: =IF(Jobs!$A9="","",Jobs!O9) | J45: =IF(Jobs!$A9="","",Jobs!S9) | K45: =IF(Jobs!$A9="","",Jobs!W9) | L45: =IF(Jobs!$A9="","",Jobs!P9)
B46: =IF(Jobs!$A10="","",Jobs!A10) | C46: =IF(Jobs!$A10="","",Jobs!B10) | D46: =IF(Jobs!$A10="","",Jobs!D10) | E46: =IF(Jobs!$A10="","",Jobs!K10) | F46: =IF(Jobs!$A10="","",Jobs!M10) | G46: =IF(Jobs!$A10="","",Jobs!T10) | H46: =IF(Jobs!$A10="","",Jobs!U10) | I46: =IF(Jobs!$A10="","",Jobs!O10) | J46: =IF(Jobs!$A10="","",Jobs!S10) | K46: =IF(Jobs!$A10="","",Jobs!W10) | L46: =IF(Jobs!$A10="","",Jobs!P10)
B47: =IF(Jobs!$A11="","",Jobs!A11) | C47: =IF(Jobs!$A11="","",Jobs!B11) | D47: =IF(Jobs!$A11="","",Jobs!D11) | E47: =IF(Jobs!$A11="","",Jobs!K11) | F47: =IF(Jobs!$A11="","",Jobs!M11) | G47: =IF(Jobs!$A11="","",Jobs!T11) | H47: =IF(Jobs!$A11="","",Jobs!U11) | I47: =IF(Jobs!$A11="","",Jobs!O11) | J47: =IF(Jobs!$A11="","",Jobs!S11) | K47: =IF(Jobs!$A11="","",Jobs!W11) | L47: =IF(Jobs!$A11="","",Jobs!P11)
B48: =IF(Jobs!$A12="","",Jobs!A12) | C48: =IF(Jobs!$A12="","",Jobs!B12) | D48: =IF(Jobs!$A12="","",Jobs!D12) | E48: =IF(Jobs!$A12="","",Jobs!K12) | F48: =IF(Jobs!$A12="","",Jobs!M12) | G48: =IF(Jobs!$A12="","",Jobs!T12) | H48: =IF(Jobs!$A12="","",Jobs!U12) | I48: =IF(Jobs!$A12="","",Jobs!O12) | J48: =IF(Jobs!$A12="","",Jobs!S12) | K48: =IF(Jobs!$A12="","",Jobs!W12) | L48: =IF(Jobs!$A12="","",Jobs!P12)
B49: =IF(Jobs!$A13="","",Jobs!A13) | C49: =IF(Jobs!$A13="","",Jobs!B13) | D49: =IF(Jobs!$A13="","",Jobs!D13) | E49: =IF(Jobs!$A13="","",Jobs!K13) | F49: =IF(Jobs!$A13="","",Jobs!M13) | G49: =IF(Jobs!$A13="","",Jobs!T13) | H49: =IF(Jobs!$A13="","",Jobs!U13) | I49: =IF(Jobs!$A13="","",Jobs!O13) | J49: =IF(Jobs!$A13="","",Jobs!S13) | K49: =IF(Jobs!$A13="","",Jobs!W13) | L49: =IF(Jobs!$A13="","",Jobs!P13)
B50: =IF(Jobs!$A14="","",Jobs!A14) | C50: =IF(Jobs!$A14="","",Jobs!B14) | D50: =IF(Jobs!$A14="","",Jobs!D14) | E50: =IF(Jobs!$A14="","",Jobs!K14) | F50: =IF(Jobs!$A14="","",Jobs!M14) | G50: =IF(Jobs!$A14="","",Jobs!T14) | H50: =IF(Jobs!$A14="","",Jobs!U14) | I50: =IF(Jobs!$A14="","",Jobs!O14) | J50: =IF(Jobs!$A14="","",Jobs!S14) | K50: =IF(Jobs!$A14="","",Jobs!W14) | L50: =IF(Jobs!$A14="","",Jobs!P14)
B51: =IF(Jobs!$A15="","",Jobs!A15) | C51: =IF(Jobs!$A15="","",Jobs!B15) | D51: =IF(Jobs!$A15="","",Jobs!D15) | E51: =IF(Jobs!$A15="","",Jobs!K15) | F51: =IF(Jobs!$A15="","",Jobs!M15) | G51: =IF(Jobs!$A15="","",Jobs!T15) | H51: =IF(Jobs!$A15="","",Jobs!U15) | I51: =IF(Jobs!$A15="","",Jobs!O15) | J51: =IF(Jobs!$A15="","",Jobs!S15) | K51: =IF(Jobs!$A15="","",Jobs!W15) | L51: =IF(Jobs!$A15="","",Jobs!P15)
B52: =IF(Jobs!$A16="","",Jobs!A16) | C52: =IF(Jobs!$A16="","",Jobs!B16) | D52: =IF(Jobs!$A16="","",Jobs!D16) | E52: =IF(Jobs!$A16="","",Jobs!K16) | F52: =IF(Jobs!$A16="","",Jobs!M16) | G52: =IF(Jobs!$A16="","",Jobs!T16) | H52: =IF(Jobs!$A16="","",Jobs!U16) | I52: =IF(Jobs!$A16="","",Jobs!O16) | J52: =IF(Jobs!$A16="","",Jobs!S16) | K52: =IF(Jobs!$A16="","",Jobs!W16) | L52: =IF(Jobs!$A16="","",Jobs!P16)
... B80: =IF(Jobs!$A44="","",Jobs!A44) | C80: =IF(Jobs!$A44="","",Jobs!B44) | D80: =IF(Jobs!$A44="","",Jobs!D44) | E80: =IF(Jobs!$A44="","",Jobs!K44) | F80: =IF(Jobs!$A44="","",Jobs!M44) | G80: =IF(Jobs!$A44="","",Jobs!T44) | H80: =IF(Jobs!$A44="","",Jobs!U44) | I80: =IF(Jobs!$A44="","",Jobs!O44) | J80: =IF(Jobs!$A44="","",Jobs!S44) | K80: =IF(Jobs!$A44="","",Jobs!W44) | L80: =IF(Jobs!$A44="","",Jobs!P44)
B82: Monthly P&L | D82: Year: | E82: =Settings!$B$14
B83: Month | C83: Invoiced | D83: Payments Received | E83: Costs (all sources) | F83: Cash Profit | G83: Cumulative | H83: Labor Hours
B84: =DATE($E$82,1,1) | C84: =SUMIFS(Invoices!$E$5:$E$204,Invoices!$C$5:$C$204,">="&B84,Invoices!$C$5:$C$204,"<="&EOMONTH(B84,0)) | D84: =SUMIFS(Payments!$D$5:$D$304,Payments!$A$5:$A$304,">="&B84,Payments!$A$5:$A$304,"<="&EOMONTH(B84,0)) | E84: =SUMIFS('Job Costs'!$I$5:$I$1004,'Job Costs'!$A$5:$A$1004,">="&B84,'Job Costs'!$A$5:$A$1004,"<="&EOMONTH(B84,0))+SUMIFS(Timesheet!$H$5:$H$1004,Timesheet!$A$5:$A$1004,">="&B84,Timesheet!$A$5:$A$1004,"<="&EOMONTH(B84,0))+SUMIFS(Mileage!$I$5:$I$304,Mileage!$A$5:$A$304,">="&B84,Mileage!$A$5:$A$304,"<="&EOMONTH(B84,0)) | F84: =D84-E84 | G84: =SUM($F$84:F84) | H84: =SUMIFS(Timesheet!$E$5:$E$1004,Timesheet!$A$5:$A$1004,">="&B84,Timesheet!$A$5:$A$1004,"<="&EOMONTH(B84,0))
B85: =DATE($E$82,2,1) | C85: =SUMIFS(Invoices!$E$5:$E$204,Invoices!$C$5:$C$204,">="&B85,Invoices!$C$5:$C$204,"<="&EOMONTH(B85,0)) | D85: =SUMIFS(Payments!$D$5:$D$304,Payments!$A$5:$A$304,">="&B85,Payments!$A$5:$A$304,"<="&EOMONTH(B85,0)) | E85: =SUMIFS('Job Costs'!$I$5:$I$1004,'Job Costs'!$A$5:$A$1004,">="&B85,'Job Costs'!$A$5:$A$1004,"<="&EOMONTH(B85,0))+SUMIFS(Timesheet!$H$5:$H$1004,Timesheet!$A$5:$A$1004,">="&B85,Timesheet!$A$5:$A$1004,"<="&EOMONTH(B85,0))+SUMIFS(Mileage!$I$5:$I$304,Mileage!$A$5:$A$304,">="&B85,Mileage!$A$5:$A$304,"<="&EOMONTH(B85,0)) | F85: =D85-E85 | G85: =SUM($F$84:F85) | H85: =SUMIFS(Timesheet!$E$5:$E$1004,Timesheet!$A$5:$A$1004,">="&B85,Timesheet!$A$5:$A$1004,"<="&EOMONTH(B85,0))
B86: =DATE($E$82,3,1) | C86: =SUMIFS(Invoices!$E$5:$E$204,Invoices!$C$5:$C$204,">="&B86,Invoices!$C$5:$C$204,"<="&EOMONTH(B86,0)) | D86: =SUMIFS(Payments!$D$5:$D$304,Payments!$A$5:$A$304,">="&B86,Payments!$A$5:$A$304,"<="&EOMONTH(B86,0)) | E86: =SUMIFS('Job Costs'!$I$5:$I$1004,'Job Costs'!$A$5:$A$1004,">="&B86,'Job Costs'!$A$5:$A$1004,"<="&EOMONTH(B86,0))+SUMIFS(Timesheet!$H$5:$H$1004,Timesheet!$A$5:$A$1004,">="&B86,Timesheet!$A$5:$A$1004,"<="&EOMONTH(B86,0))+SUMIFS(Mileage!$I$5:$I$304,Mileage!$A$5:$A$304,">="&B86,Mileage!$A$5:$A$304,"<="&EOMONTH(B86,0)) | F86: =D86-E86 | G86: =SUM($F$84:F86) | H86: =SUMIFS(Timesheet!$E$5:$E$1004,Timesheet!$A$5:$A$1004,">="&B86,Timesheet!$A$5:$A$1004,"<="&EOMONTH(B86,0))
B87: =DATE($E$82,4,1) | C87: =SUMIFS(Invoices!$E$5:$E$204,Invoices!$C$5:$C$204,">="&B87,Invoices!$C$5:$C$204,"<="&EOMONTH(B87,0)) | D87: =SUMIFS(Payments!$D$5:$D$304,Payments!$A$5:$A$304,">="&B87,Payments!$A$5:$A$304,"<="&EOMONTH(B87,0)) | E87: =SUMIFS('Job Costs'!$I$5:$I$1004,'Job Costs'!$A$5:$A$1004,">="&B87,'Job Costs'!$A$5:$A$1004,"<="&EOMONTH(B87,0))+SUMIFS(Timesheet!$H$5:$H$1004,Timesheet!$A$5:$A$1004,">="&B87,Timesheet!$A$5:$A$1004,"<="&EOMONTH(B87,0))+SUMIFS(Mileage!$I$5:$I$304,Mileage!$A$5:$A$304,">="&B87,Mileage!$A$5:$A$304,"<="&EOMONTH(B87,0)) | F87: =D87-E87 | G87: =SUM($F$84:F87) | H87: =SUMIFS(Timesheet!$E$5:$E$1004,Timesheet!$A$5:$A$1004,">="&B87,Timesheet!$A$5:$A$1004,"<="&EOMONTH(B87,0))
B88: =DATE($E$82,5,1) | C88: =SUMIFS(Invoices!$E$5:$E$204,Invoices!$C$5:$C$204,">="&B88,Invoices!$C$5:$C$204,"<="&EOMONTH(B88,0)) | D88: =SUMIFS(Payments!$D$5:$D$304,Payments!$A$5:$A$304,">="&B88,Payments!$A$5:$A$304,"<="&EOMONTH(B88,0)) | E88: =SUMIFS('Job Costs'!$I$5:$I$1004,'Job Costs'!$A$5:$A$1004,">="&B88,'Job Costs'!$A$5:$A$1004,"<="&EOMONTH(B88,0))+SUMIFS(Timesheet!$H$5:$H$1004,Timesheet!$A$5:$A$1004,">="&B88,Timesheet!$A$5:$A$1004,"<="&EOMONTH(B88,0))+SUMIFS(Mileage!$I$5:$I$304,Mileage!$A$5:$A$304,">="&B88,Mileage!$A$5:$A$304,"<="&EOMONTH(B88,0)) | F88: =D88-E88 | G88: =SUM($F$84:F88) | H88: =SUMIFS(Timesheet!$E$5:$E$1004,Timesheet!$A$5:$A$1004,">="&B88,Timesheet!$A$5:$A$1004,"<="&EOMONTH(B88,0))
B89: =DATE($E$82,6,1) | C89: =SUMIFS(Invoices!$E$5:$E$204,Invoices!$C$5:$C$204,">="&B89,Invoices!$C$5:$C$204,"<="&EOMONTH(B89,0)) | D89: =SUMIFS(Payments!$D$5:$D$304,Payments!$A$5:$A$304,">="&B89,Payments!$A$5:$A$304,"<="&EOMONTH(B89,0)) | E89: =SUMIFS('Job Costs'!$I$5:$I$1004,'Job Costs'!$A$5:$A$1004,">="&B89,'Job Costs'!$A$5:$A$1004,"<="&EOMONTH(B89,0))+SUMIFS(Timesheet!$H$5:$H$1004,Timesheet!$A$5:$A$1004,">="&B89,Timesheet!$A$5:$A$1004,"<="&EOMONTH(B89,0))+SUMIFS(Mileage!$I$5:$I$304,Mileage!$A$5:$A$304,">="&B89,Mileage!$A$5:$A$304,"<="&EOMONTH(B89,0)) | F89: =D89-E89 | G89: =SUM($F$84:F89) | H89: =SUMIFS(Timesheet!$E$5:$E$1004,Timesheet!$A$5:$A$1004,">="&B89,Timesheet!$A$5:$A$1004,"<="&EOMONTH(B89,0))
...

Sheet Settings
A1: Settings
A2: Light-blue cells are inputs. Everything here feeds dropdowns, markups, documents and reports on the other sheets.
A4: Company & defaults | B4: Value | E4: Code | F4: Cost code name | G4: Category | I4: Job status | J4: Units | K4: Payment methods | L4: Vendor types
A5: Company name | B5: Your Company LLC | E5: 01 | F5: General conditions / supervision | G5: Labor | I5: Lead | J5: ea | K5: Check | L5: Subcontractor
A6: Address | E6: 02 | F6: Demolition & disposal | G6: Labor | I6: Quoted | J6: hr | K6: ACH / Bank | L6: Supplier
A7: Phone / email | E7: 03 | F7: Site work & excavation | G7: Subcontractor | I7: Approved | J7: day | K7: Card | L7: Equipment rental
A8: License # | E8: 04 | F8: Concrete & foundation | G8: Subcontractor | I8: In Progress | J8: sq ft | K8: Cash | L8: Other
A9: Default contingency % | B9: 0.05 | E9: 05 | F9: Framing labor | G9: Labor | I9: Complete | J9: lin ft | K9: Zelle
A10: Sales tax % | B10: 0 | E10: 06 | F10: Lumber & framing materials | G10: Material | I10: Closed | J10: sq yd | K10: Other
A11: Deposit % of proposal total | B11: 0.3 | E11: 07 | F11: Roofing | G11: Subcontractor | I11: Lost | J11: cu yd
A12: Progress payment % (mid-job) | B12: 0.4 | E12: 08 | F12: Windows & doors | G12: Material | J12: gal
A13: Overdue grace (days past due) | B13: 0 | E13: 09 | F13: Exterior finishes / siding | G13: Subcontractor | J13: box
A14: Reporting / tax year | B14: 2026 | E14: 10 | F14: Plumbing | G14: Subcontractor | J14: lot
A15: Mileage rate ($ per mile) | B15: 0.7 | C15: Check the current IRS standard mileage rate each January. | E15: 11 | F15: Electrical | G15: Subcontractor
A16: Proposal valid for (days) | B16: 30 | E16: 12 | F16: HVAC | G16: Subcontractor
A17: Overhead % of revenue (for net margin) | B17: 0.1 | C17: Used for 'margin after overhead' on the Dashboard and Job Profit Report. | E17: 13 | F17: Insulation & drywall | G17: Subcontractor
A18: Labor burden % (payroll taxes, insurance, added to crew cost) | B18: 0 | C18: Applied on the Timesheet: Labor cost = hours × rate × (1 + burden). | E18: 14 | F18: Interior finish labor | G18: Labor
A19: Sales tax applies to | B19: Material only | C19: Material only = tax on Material lines. All lines = tax on the whole subtotal. | E19: 15 | F19: Paint & wall finishes | G19: Material
E20: 16 | F20: Flooring & tile | G20: Material
A21: Cost category | B21: Default markup % | E21: 17 | F21: Cabinets & countertops | G21: Material
A22: Labor | B22: 0.35 | E22: 18 | F22: Fixtures & appliances | G22: Material
A23: Material | B23: 0.2 | E23: 19 | F23: Equipment rental | G23: Equipment
A24: Subcontractor | B24: 0.15 | E24: 20 | F24: Permits & inspections | G24: Permit/Fee
A25: Equipment | B25: 0.15 | E25: 21 | F25: Dumpster & cleanup | G25: Other
A26: Permit/Fee | B26: 0 | E26: 22 | F26: Fuel & mileage | G26: Other
A27: Other | B27: 0.1 | E27: 23 | F27: Warranty / callbacks | G27: Labor
A28: Markup is applied to cost: Price = Cost × (1 + markup). Override per line on the Estimate. | E28: 24 | F28: Miscellaneous | G28: Other
A29: Document text | B29: Value
A30: Proposal terms | B30: This proposal is valid until the date shown. Work begins on receipt of the deposit. Changes to scope are priced as written change orders before work proceeds. Balance is due on completion.
A31: Invoice payment instructions | B31: Pay by check to the company name above, or by bank transfer. Please reference the invoice number.
A32: Invoice / statement footer | B32: Thank you for your business.
A33: Change order terms | B33: The client authorizes the added work and price above. The revised contract total and any schedule change apply from the date signed.
A34: Proposal exclusions & assumptions | B34: Excludes permits not listed, hazardous-material remediation, structural repairs discovered after demolition, and work outside the described scope. Pricing assumes access to water and power on site.
A35: Logo: on Proposal, Invoice Print, CO Form or Client Statement use Insert → Pictures and place it top-right.

Sheet Clients
A1: Clients
A2: One row per client. Jobs, contract value, collected and balance due are calculated from the Jobs sheet. Print a statement from the Client Statement sheet.
A4: Client | B4: Contact person | C4: Phone | D4: Email | E4: Billing address | F4: Notes | G4: Jobs | H4: Contract value (all jobs) | I4: Collected | J4: Balance due | K4: Check
G5: =IF(A5="","",COUNTIF(Jobs!$B$5:$B$44,A5)) | H5: =IF(A5="","",SUMIFS(Jobs!$K$5:$K$44,Jobs!$B$5:$B$44,A5)) | I5: =IF(A5="","",SUMIFS(Jobs!$R$5:$R$44,Jobs!$B$5:$B$44,A5)) | J5: =IF(A5="","",SUMIFS(Jobs!$S$5:$S$44,Jobs!$B$5:$B$44,A5)) | K5: =IF(A5="","",IF(COUNTIF(Clients!$A$5:$A$104,A5)>1,"Duplicate client",""))
G6: =IF(A6="","",COUNTIF(Jobs!$B$5:$B$44,A6)) | H6: =IF(A6="","",SUMIFS(Jobs!$K$5:$K$44,Jobs!$B$5:$B$44,A6)) | I6: =IF(A6="","",SUMIFS(Jobs!$R$5:$R$44,Jobs!$B$5:$B$44,A6)) | J6: =IF(A6="","",SUMIFS(Jobs!$S$5:$S$44,Jobs!$B$5:$B$44,A6)) | K6: =IF(A6="","",IF(COUNTIF(Clients!$A$5:$A$104,A6)>1,"Duplicate client",""))
G7: =IF(A7="","",COUNTIF(Jobs!$B$5:$B$44,A7)) | H7: =IF(A7="","",SUMIFS(Jobs!$K$5:$K$44,Jobs!$B$5:$B$44,A7)) | I7: =IF(A7="","",SUMIFS(Jobs!$R$5:$R$44,Jobs!$B$5:$B$44,A7)) | J7: =IF(A7="","",SUMIFS(Jobs!$S$5:$S$44,Jobs!$B$5:$B$44,A7)) | K7: =IF(A7="","",IF(COUNTIF(Clients!$A$5:$A$104,A7)>1,"Duplicate client",""))
G8: =IF(A8="","",COUNTIF(Jobs!$B$5:$B$44,A8)) | H8: =IF(A8="","",SUMIFS(Jobs!$K$5:$K$44,Jobs!$B$5:$B$44,A8)) | I8: =IF(A8="","",SUMIFS(Jobs!$R$5:$R$44,Jobs!$B$5:$B$44,A8)) | J8: =IF(A8="","",SUMIFS(Jobs!$S$5:$S$44,Jobs!$B$5:$B$44,A8)) | K8: =IF(A8="","",IF(COUNTIF(Clients!$A$5:$A$104,A8)>1,"Duplicate client",""))
G9: =IF(A9="","",COUNTIF(Jobs!$B$5:$B$44,A9)) | H9: =IF(A9="","",SUMIFS(Jobs!$K$5:$K$44,Jobs!$B$5:$B$44,A9)) | I9: =IF(A9="","",SUMIFS(Jobs!$R$5:$R$44,Jobs!$B$5:$B$44,A9)) | J9: =IF(A9="","",SUMIFS(Jobs!$S$5:$S$44,Jobs!$B$5:$B$44,A9)) | K9: =IF(A9="","",IF(COUNTIF(Clients!$A$5:$A$104,A9)>1,"Duplicate client",""))
G10: =IF(A10="","",COUNTIF(Jobs!$B$5:$B$44,A10)) | H10: =IF(A10="","",SUMIFS(Jobs!$K$5:$K$44,Jobs!$B$5:$B$44,A10)) | I10: =IF(A10="","",SUMIFS(Jobs!$R$5:$R$44,Jobs!$B$5:$B$44,A10)) | J10: =IF(A10="","",SUMIFS(Jobs!$S$5:$S$44,Jobs!$B$5:$B$44,A10)) | K10: =IF(A10="","",IF(COUNTIF(Clients!$A$5:$A$104,A10)>1,"Duplicate client",""))
G11: =IF(A11="","",COUNTIF(Jobs!$B$5:$B$44,A11)) | H11: =IF(A11="","",SUMIFS(Jobs!$K$5:$K$44,Jobs!$B$5:$B$44,A11)) | I11: =IF(A11="","",SUMIFS(Jobs!$R$5:$R$44,Jobs!$B$5:$B$44,A11)) | J11: =IF(A11="","",SUMIFS(Jobs!$S$5:$S$44,Jobs!$B$5:$B$44,A11)) | K11: =IF(A11="","",IF(COUNTIF(Clients!$A$5:$A$104,A11)>1,"Duplicate client",""))
G12: =IF(A12="","",COUNTIF(Jobs!$B$5:$B$44,A12)) | H12: =IF(A12="","",SUMIFS(Jobs!$K$5:$K$44,Jobs!$B$5:$B$44,A12)) | I12: =IF(A12="","",SUMIFS(Jobs!$R$5:$R$44,Jobs!$B$5:$B$44,A12)) | J12: =IF(A12="","",SUMIFS(Jobs!$S$5:$S$44,Jobs!$B$5:$B$44,A12)) | K12: =IF(A12="","",IF(COUNTIF(Clients!$A$5:$A$104,A12)>1,"Duplicate client",""))
G13: =IF(A13="","",COUNTIF(Jobs!$B$5:$B$44,A13)) | H13: =IF(A13="","",SUMIFS(Jobs!$K$5:$K$44,Jobs!$B$5:$B$44,A13)) | I13: =IF(A13="","",SUMIFS(Jobs!$R$5:$R$44,Jobs!$B$5:$B$44,A13)) | J13: =IF(A13="","",SUMIFS(Jobs!$S$5:$S$44,Jobs!$B$5:$B$44,A13)) | K13: =IF(A13="","",IF(COUNTIF(Clients!$A$5:$A$104,A13)>1,"Duplicate client",""))
G14: =IF(A14="","",COUNTIF(Jobs!$B$5:$B$44,A14)) | H14: =IF(A14="","",SUMIFS(Jobs!$K$5:$K$44,Jobs!$B$5:$B$44,A14)) | I14: =IF(A14="","",SUMIFS(Jobs!$R$5:$R$44,Jobs!$B$5:$B$44,A14)) | J14: =IF(A14="","",SUMIFS(Jobs!$S$5:$S$44,Jobs!$B$5:$B$44,A14)) | K14: =IF(A14="","",IF(COUNTIF(Clients!$A$5:$A$104,A14)>1,"Duplicate client",""))
G15: =IF(A15="","",COUNTIF(Jobs!$B$5:$B$44,A15)) | H15: =IF(A15="","",SUMIFS(Jobs!$K$5:$K$44,Jobs!$B$5:$B$44,A15)) | I15: =IF(A15="","",SUMIFS(Jobs!$R$5:$R$44,Jobs!$B$5:$B$44,A15)) | J15: =IF(A15="","",SUMIFS(Jobs!$S$5:$S$44,Jobs!$B$5:$B$44,A15)) | K15: =IF(A15="","",IF(COUNTIF(Clients!$A$5:$A$104,A15)>1,"Duplicate client",""))
G16: =IF(A16="","",COUNTIF(Jobs!$B$5:$B$44,A16)) | H16: =IF(A16="","",SUMIFS(Jobs!$K$5:$K$44,Jobs!$B$5:$B$44,A16)) | I16: =IF(A16="","",SUMIFS(Jobs!$R$5:$R$44,Jobs!$B$5:$B$44,A16)) | J16: =IF(A16="","",SUMIFS(Jobs!$S$5:$S$44,Jobs!$B$5:$B$44,A16)) | K16: =IF(A16="","",IF(COUNTIF(Clients!$A$5:$A$104,A16)>1,"Duplicate client",""))
... G104: =IF(A104="","",COUNTIF(Jobs!$B$5:$B$44,A104)) | H104: =IF(A104="","",SUMIFS(Jobs!$K$5:$K$44,Jobs!$B$5:$B$44,A104)) | I104: =IF(A104="","",SUMIFS(Jobs!$R$5:$R$44,Jobs!$B$5:$B$44,A104)) | J104: =IF(A104="","",SUMIFS(Jobs!$S$5:$S$44,Jobs!$B$5:$B$44,A104)) | K104: =IF(A104="","",IF(COUNTIF(Clients!$A$5:$A$104,A104)>1,"Duplicate client",""))

Sheet Vendors & Crew
A1: Vendors & Crew
A2: Crew (your workers, with cost and bill rates) feeds the Timesheet. Vendors & subs feed Job Costs, insurance alerts and the 1099 review.
A3: CREW
A4: Worker | B4: Role | C4: Cost Rate ($/hr) | D4: Bill Rate ($/hr) | E4: Phone | F4: Hours YTD | G4: Labor Cost YTD | H4: Check | I4: Notes
F5: =IF(A5="","",SUMIFS(Timesheet!$E$5:$E$1004,Timesheet!$B$5:$B$1004,A5,Timesheet!$A$5:$A$1004,">="&DATE(Settings!$B$14,1,1),Timesheet!$A$5:$A$1004,"<="&DATE(Settings!$B$14,12,31))) | G5: =IF(A5="","",SUMIFS(Timesheet!$H$5:$H$1004,Timesheet!$B$5:$B$1004,A5,Timesheet!$A$5:$A$1004,">="&DATE(Settings!$B$14,1,1),Timesheet!$A$5:$A$1004,"<="&DATE(Settings!$B$14,12,31))) | H5: =IF(A5="","",IF(COUNTIF('Vendors & Crew'!$A$5:$A$34,A5)>1,"Duplicate worker",IF(C5="","Missing cost rate","")))
F6: =IF(A6="","",SUMIFS(Timesheet!$E$5:$E$1004,Timesheet!$B$5:$B$1004,A6,Timesheet!$A$5:$A$1004,">="&DATE(Settings!$B$14,1,1),Timesheet!$A$5:$A$1004,"<="&DATE(Settings!$B$14,12,31))) | G6: =IF(A6="","",SUMIFS(Timesheet!$H$5:$H$1004,Timesheet!$B$5:$B$1004,A6,Timesheet!$A$5:$A$1004,">="&DATE(Settings!$B$14,1,1),Timesheet!$A$5:$A$1004,"<="&DATE(Settings!$B$14,12,31))) | H6: =IF(A6="","",IF(COUNTIF('Vendors & Crew'!$A$5:$A$34,A6)>1,"Duplicate worker",IF(C6="","Missing cost rate","")))
F7: =IF(A7="","",SUMIFS(Timesheet!$E$5:$E$1004,Timesheet!$B$5:$B$1004,A7,Timesheet!$A$5:$A$1004,">="&DATE(Settings!$B$14,1,1),Timesheet!$A$5:$A$1004,"<="&DATE(Settings!$B$14,12,31))) | G7: =IF(A7="","",SUMIFS(Timesheet!$H$5:$H$1004,Timesheet!$B$5:$B$1004,A7,Timesheet!$A$5:$A$1004,">="&DATE(Settings!$B$14,1,1),Timesheet!$A$5:$A$1004,"<="&DATE(Settings!$B$14,12,31))) | H7: =IF(A7="","",IF(COUNTIF('Vendors & Crew'!$A$5:$A$34,A7)>1,"Duplicate worker",IF(C7="","Missing cost rate","")))
F8: =IF(A8="","",SUMIFS(Timesheet!$E$5:$E$1004,Timesheet!$B$5:$B$1004,A8,Timesheet!$A$5:$A$1004,">="&DATE(Settings!$B$14,1,1),Timesheet!$A$5:$A$1004,"<="&DATE(Settings!$B$14,12,31))) | G8: =IF(A8="","",SUMIFS(Timesheet!$H$5:$H$1004,Timesheet!$B$5:$B$1004,A8,Timesheet!$A$5:$A$1004,">="&DATE(Settings!$B$14,1,1),Timesheet!$A$5:$A$1004,"<="&DATE(Settings!$B$14,12,31))) | H8: =IF(A8="","",IF(COUNTIF('Vendors & Crew'!$A$5:$A$34,A8)>1,"Duplicate worker",IF(C8="","Missing cost rate","")))
F9: =IF(A9="","",SUMIFS(Timesheet!$E$5:$E$1004,Timesheet!$B$5:$B$1004,A9,Timesheet!$A$5:$A$1004,">="&DATE(Settings!$B$14,1,1),Timesheet!$A$5:$A$1004,"<="&DATE(Settings!$B$14,12,31))) | G9: =IF(A9="","",SUMIFS(Timesheet!$H$5:$H$1004,Timesheet!$B$5:$B$1004,A9,Timesheet!$A$5:$A$1004,">="&DATE(Settings!$B$14,1,1),Timesheet!$A$5:$A$1004,"<="&DATE(Settings!$B$14,12,31))) | H9: =IF(A9="","",IF(COUNTIF('Vendors & Crew'!$A$5:$A$34,A9)>1,"Duplicate worker",IF(C9="","Missing cost rate","")))
F10: =IF(A10="","",SUMIFS(Timesheet!$E$5:$E$1004,Timesheet!$B$5:$B$1004,A10,Timesheet!$A$5:$A$1004,">="&DATE(Settings!$B$14,1,1),Timesheet!$A$5:$A$1004,"<="&DATE(Settings!$B$14,12,31))) | G10: =IF(A10="","",SUMIFS(Timesheet!$H$5:$H$1004,Timesheet!$B$5:$B$1004,A10,Timesheet!$A$5:$A$1004,">="&DATE(Settings!$B$14,1,1),Timesheet!$A$5:$A$1004,"<="&DATE(Settings!$B$14,12,31))) | H10: =IF(A10="","",IF(COUNTIF('Vendors & Crew'!$A$5:$A$34,A10)>1,"Duplicate worker",IF(C10="","Missing cost rate","")))
F11: =IF(A11="","",SUMIFS(Timesheet!$E$5:$E$1004,Timesheet!$B$5:$B$1004,A11,Timesheet!$A$5:$A$1004,">="&DATE(Settings!$B$14,1,1),Timesheet!$A$5:$A$1004,"<="&DATE(Settings!$B$14,12,31))) | G11: =IF(A11="","",SUMIFS(Timesheet!$H$5:$H$1004,Timesheet!$B$5:$B$1004,A11,Timesheet!$A$5:$A$1004,">="&DATE(Settings!$B$14,1,1),Timesheet!$A$5:$A$1004,"<="&DATE(Settings!$B$14,12,31))) | H11: =IF(A11="","",IF(COUNTIF('Vendors & Crew'!$A$5:$A$34,A11)>1,"Duplicate worker",IF(C11="","Missing cost rate","")))
F12: =IF(A12="","",SUMIFS(Timesheet!$E$5:$E$1004,Timesheet!$B$5:$B$1004,A12,Timesheet!$A$5:$A$1004,">="&DATE(Settings!$B$14,1,1),Timesheet!$A$5:$A$1004,"<="&DATE(Settings!$B$14,12,31))) | G12: =IF(A12="","",SUMIFS(Timesheet!$H$5:$H$1004,Timesheet!$B$5:$B$1004,A12,Timesheet!$A$5:$A$1004,">="&DATE(Settings!$B$14,1,1),Timesheet!$A$5:$A$1004,"<="&DATE(Settings!$B$14,12,31))) | H12: =IF(A12="","",IF(COUNTIF('Vendors & Crew'!$A$5:$A$34,A12)>1,"Duplicate worker",IF(C12="","Missing cost rate","")))
F13: =IF(A13="","",SUMIFS(Timesheet!$E$5:$E$1004,Timesheet!$B$5:$B$1004,A13,Timesheet!$A$5:$A$1004,">="&DATE(Settings!$B$14,1,1),Timesheet!$A$5:$A$1004,"<="&DATE(Settings!$B$14,12,31))) | G13: =IF(A13="","",SUMIFS(Timesheet!$H$5:$H$1004,Timesheet!$B$5:$B$1004,A13,Timesheet!$A$5:$A$1004,">="&DATE(Settings!$B$14,1,1),Timesheet!$A$5:$A$1004,"<="&DATE(Settings!$B$14,12,31))) | H13: =IF(A13="","",IF(COUNTIF('Vendors & Crew'!$A$5:$A$34,A13)>1,"Duplicate worker",IF(C13="","Missing cost rate","")))
F14: =IF(A14="","",SUMIFS(Timesheet!$E$5:$E$1004,Timesheet!$B$5:$B$1004,A14,Timesheet!$A$5:$A$1004,">="&DATE(Settings!$B$14,1,1),Timesheet!$A$5:$A$1004,"<="&DATE(Settings!$B$14,12,31))) | G14: =IF(A14="","",SUMIFS(Timesheet!$H$5:$H$1004,Timesheet!$B$5:$B$1004,A14,Timesheet!$A$5:$A$1004,">="&DATE(Settings!$B$14,1,1),Timesheet!$A$5:$A$1004,"<="&DATE(Settings!$B$14,12,31))) | H14: =IF(A14="","",IF(COUNTIF('Vendors & Crew'!$A$5:$A$34,A14)>1,"Duplicate worker",IF(C14="","Missing cost rate","")))
F15: =IF(A15="","",SUMIFS(Timesheet!$E$5:$E$1004,Timesheet!$B$5:$B$1004,A15,Timesheet!$A$5:$A$1004,">="&DATE(Settings!$B$14,1,1),Timesheet!$A$5:$A$1004,"<="&DATE(Settings!$B$14,12,31))) | G15: =IF(A15="","",SUMIFS(Timesheet!$H$5:$H$1004,Timesheet!$B$5:$B$1004,A15,Timesheet!$A$5:$A$1004,">="&DATE(Settings!$B$14,1,1),Timesheet!$A$5:$A$1004,"<="&DATE(Settings!$B$14,12,31))) | H15: =IF(A15="","",IF(COUNTIF('Vendors & Crew'!$A$5:$A$34,A15)>1,"Duplicate worker",IF(C15="","Missing cost rate","")))
F16: =IF(A16="","",SUMIFS(Timesheet!$E$5:$E$1004,Timesheet!$B$5:$B$1004,A16,Timesheet!$A$5:$A$1004,">="&DATE(Settings!$B$14,1,1),Timesheet!$A$5:$A$1004,"<="&DATE(Settings!$B$14,12,31))) | G16: =IF(A16="","",SUMIFS(Timesheet!$H$5:$H$1004,Timesheet!$B$5:$B$1004,A16,Timesheet!$A$5:$A$1004,">="&DATE(Settings!$B$14,1,1),Timesheet!$A$5:$A$1004,"<="&DATE(Settings!$B$14,12,31))) | H16: =IF(A16="","",IF(COUNTIF('Vendors & Crew'!$A$5:$A$34,A16)>1,"Duplicate worker",IF(C16="","Missing cost rate","")))
... F34: =IF(A34="","",SUMIFS(Timesheet!$E$5:$E$1004,Timesheet!$B$5:$B$1004,A34,Timesheet!$A$5:$A$1004,">="&DATE(Settings!$B$14,1,1),Timesheet!$A$5:$A$1004,"<="&DATE(Settings!$B$14,12,31))) | G34: =IF(A34="","",SUMIFS(Timesheet!$H$5:$H$1004,Timesheet!$B$5:$B$1004,A34,Timesheet!$A$5:$A$1004,">="&DATE(Settings!$B$14,1,1),Timesheet!$A$5:$A$1004,"<="&DATE(Settings!$B$14,12,31))) | H34: =IF(A34="","",IF(COUNTIF('Vendors & Crew'!$A$5:$A$34,A34)>1,"Duplicate worker",IF(C34="","Missing cost rate","")))
A39: VENDORS & SUBCONTRACTORS
A40: Vendor / Sub | B40: Type | C40: Trade | D40: Phone | E40: Email | F40: License # | G40: Insurance Expiry | H40: Insurance Status | I40: W-9 on file | J40: 1099-eligible | K40: Paid YTD | L40: Unpaid Balance | M40: 1099 Flag | N40: Check | O40: Notes
H41: =IF(A41="","",IF(G41="","No expiry on file",IF(G41<TODAY(),"EXPIRED",IF(G41-TODAY()<=30,"Expiring soon","OK")))) | K41: =IF(A41="","",SUMIFS('Job Costs'!$I$5:$I$1004,'Job Costs'!$E$5:$E$1004,A41,'Job Costs'!$A$5:$A$1004,">="&DATE(Settings!$B$14,1,1),'Job Costs'!$A$5:$A$1004,"<="&DATE(Settings!$B$14,12,31))) | L41: =IF(A41="","",SUMIFS('Job Costs'!$I$5:$I$1004,'Job Costs'!$E$5:$E$1004,A41,'Job Costs'!$J$5:$J$1004,"No")) | M41: =IF(A41="","",IF(AND(J41="Yes",K41>=600),"Review for 1099","")) | N41: =IF(A41="","",IF(COUNTIF('Vendors & Crew'!$A$41:$A$140,A41)>1,"Duplicate vendor",""))
H42: =IF(A42="","",IF(G42="","No expiry on file",IF(G42<TODAY(),"EXPIRED",IF(G42-TODAY()<=30,"Expiring soon","OK")))) | K42: =IF(A42="","",SUMIFS('Job Costs'!$I$5:$I$1004,'Job Costs'!$E$5:$E$1004,A42,'Job Costs'!$A$5:$A$1004,">="&DATE(Settings!$B$14,1,1),'Job Costs'!$A$5:$A$1004,"<="&DATE(Settings!$B$14,12,31))) | L42: =IF(A42="","",SUMIFS('Job Costs'!$I$5:$I$1004,'Job Costs'!$E$5:$E$1004,A42,'Job Costs'!$J$5:$J$1004,"No")) | M42: =IF(A42="","",IF(AND(J42="Yes",K42>=600),"Review for 1099","")) | N42: =IF(A42="","",IF(COUNTIF('Vendors & Crew'!$A$41:$A$140,A42)>1,"Duplicate vendor",""))
H43: =IF(A43="","",IF(G43="","No expiry on file",IF(G43<TODAY(),"EXPIRED",IF(G43-TODAY()<=30,"Expiring soon","OK")))) | K43: =IF(A43="","",SUMIFS('Job Costs'!$I$5:$I$1004,'Job Costs'!$E$5:$E$1004,A43,'Job Costs'!$A$5:$A$1004,">="&DATE(Settings!$B$14,1,1),'Job Costs'!$A$5:$A$1004,"<="&DATE(Settings!$B$14,12,31))) | L43: =IF(A43="","",SUMIFS('Job Costs'!$I$5:$I$1004,'Job Costs'!$E$5:$E$1004,A43,'Job Costs'!$J$5:$J$1004,"No")) | M43: =IF(A43="","",IF(AND(J43="Yes",K43>=600),"Review for 1099","")) | N43: =IF(A43="","",IF(COUNTIF('Vendors & Crew'!$A$41:$A$140,A43)>1,"Duplicate vendor",""))
H44: =IF(A44="","",IF(G44="","No expiry on file",IF(G44<TODAY(),"EXPIRED",IF(G44-TODAY()<=30,"Expiring soon","OK")))) | K44: =IF(A44="","",SUMIFS('Job Costs'!$I$5:$I$1004,'Job Costs'!$E$5:$E$1004,A44,'Job Costs'!$A$5:$A$1004,">="&DATE(Settings!$B$14,1,1),'Job Costs'!$A$5:$A$1004,"<="&DATE(Settings!$B$14,12,31))) | L44: =IF(A44="","",SUMIFS('Job Costs'!$I$5:$I$1004,'Job Costs'!$E$5:$E$1004,A44,'Job Costs'!$J$5:$J$1004,"No")) | M44: =IF(A44="","",IF(AND(J44="Yes",K44>=600),"Review for 1099","")) | N44: =IF(A44="","",IF(COUNTIF('Vendors & Crew'!$A$41:$A$140,A44)>1,"Duplicate vendor",""))
H45: =IF(A45="","",IF(G45="","No expiry on file",IF(G45<TODAY(),"EXPIRED",IF(G45-TODAY()<=30,"Expiring soon","OK")))) | K45: =IF(A45="","",SUMIFS('Job Costs'!$I$5:$I$1004,'Job Costs'!$E$5:$E$1004,A45,'Job Costs'!$A$5:$A$1004,">="&DATE(Settings!$B$14,1,1),'Job Costs'!$A$5:$A$1004,"<="&DATE(Settings!$B$14,12,31))) | L45: =IF(A45="","",SUMIFS('Job Costs'!$I$5:$I$1004,'Job Costs'!$E$5:$E$1004,A45,'Job Costs'!$J$5:$J$1004,"No")) | M45: =IF(A45="","",IF(AND(J45="Yes",K45>=600),"Review for 1099","")) | N45: =IF(A45="","",IF(COUNTIF('Vendors & Crew'!$A$41:$A$140,A45)>1,"Duplicate vendor",""))
H46: =IF(A46="","",IF(G46="","No expiry on file",IF(G46<TODAY(),"EXPIRED",IF(G46-TODAY()<=30,"Expiring soon","OK")))) | K46: =IF(A46="","",SUMIFS('Job Costs'!$I$5:$I$1004,'Job Costs'!$E$5:$E$1004,A46,'Job Costs'!$A$5:$A$1004,">="&DATE(Settings!$B$14,1,1),'Job Costs'!$A$5:$A$1004,"<="&DATE(Settings!$B$14,12,31))) | L46: =IF(A46="","",SUMIFS('Job Costs'!$I$5:$I$1004,'Job Costs'!$E$5:$E$1004,A46,'Job Costs'!$J$5:$J$1004,"No")) | M46: =IF(A46="","",IF(AND(J46="Yes",K46>=600),"Review for 1099","")) | N46: =IF(A46="","",IF(COUNTIF('Vendors & Crew'!$A$41:$A$140,A46)>1,"Duplicate vendor",""))
H47: =IF(A47="","",IF(G47="","No expiry on file",IF(G47<TODAY(),"EXPIRED",IF(G47-TODAY()<=30,"Expiring soon","OK")))) | K47: =IF(A47="","",SUMIFS('Job Costs'!$I$5:$I$1004,'Job Costs'!$E$5:$E$1004,A47,'Job Costs'!$A$5:$A$1004,">="&DATE(Settings!$B$14,1,1),'Job Costs'!$A$5:$A$1004,"<="&DATE(Settings!$B$14,12,31))) | L47: =IF(A47="","",SUMIFS('Job Costs'!$I$5:$I$1004,'Job Costs'!$E$5:$E$1004,A47,'Job Costs'!$J$5:$J$1004,"No")) | M47: =IF(A47="","",IF(AND(J47="Yes",K47>=600),"Review for 1099","")) | N47: =IF(A47="","",IF(COUNTIF('Vendors & Crew'!$A$41:$A$140,A47)>1,"Duplicate vendor",""))
H48: =IF(A48="","",IF(G48="","No expiry on file",IF(G48<TODAY(),"EXPIRED",IF(G48-TODAY()<=30,"Expiring soon","OK")))) | K48: =IF(A48="","",SUMIFS('Job Costs'!$I$5:$I$1004,'Job Costs'!$E$5:$E$1004,A48,'Job Costs'!$A$5:$A$1004,">="&DATE(Settings!$B$14,1,1),'Job Costs'!$A$5:$A$1004,"<="&DATE(Settings!$B$14,12,31))) | L48: =IF(A48="","",SUMIFS('Job Costs'!$I$5:$I$1004,'Job Costs'!$E$5:$E$1004,A48,'Job Costs'!$J$5:$J$1004,"No")) | M48: =IF(A48="","",IF(AND(J48="Yes",K48>=600),"Review for 1099","")) | N48: =IF(A48="","",IF(COUNTIF('Vendors & Crew'!$A$41:$A$140,A48)>1,"Duplicate vendor",""))
H49: =IF(A49="","",IF(G49="","No expiry on file",IF(G49<TODAY(),"EXPIRED",IF(G49-TODAY()<=30,"Expiring soon","OK")))) | K49: =IF(A49="","",SUMIFS('Job Costs'!$I$5:$I$1004,'Job Costs'!$E$5:$E$1004,A49,'Job Costs'!$A$5:$A$1004,">="&DATE(Settings!$B$14,1,1),'Job Costs'!$A$5:$A$1004,"<="&DATE(Settings!$B$14,12,31))) | L49: =IF(A49="","",SUMIFS('Job Costs'!$I$5:$I$1004,'Job Costs'!$E$5:$E$1004,A49,'Job Costs'!$J$5:$J$1004,"No")) | M49: =IF(A49="","",IF(AND(J49="Yes",K49>=600),"Review for 1099","")) | N49: =IF(A49="","",IF(COUNTIF('Vendors & Crew'!$A$41:$A$140,A49)>1,"Duplicate vendor",""))
H50: =IF(A50="","",IF(G50="","No expiry on file",IF(G50<TODAY(),"EXPIRED",IF(G50-TODAY()<=30,"Expiring soon","OK")))) | K50: =IF(A50="","",SUMIFS('Job Costs'!$I$5:$I$1004,'Job Costs'!$E$5:$E$1004,A50,'Job Costs'!$A$5:$A$1004,">="&DATE(Settings!$B$14,1,1),'Job Costs'!$A$5:$A$1004,"<="&DATE(Settings!$B$14,12,31))) | L50: =IF(A50="","",SUMIFS('Job Costs'!$I$5:$I$1004,'Job Costs'!$E$5:$E$1004,A50,'Job Costs'!$J$5:$J$1004,"No")) | M50: =IF(A50="","",IF(AND(J50="Yes",K50>=600),"Review for 1099","")) | N50: =IF(A50="","",IF(COUNTIF('Vendors & Crew'!$A$41:$A$140,A50)>1,"Duplicate vendor",""))
H51: =IF(A51="","",IF(G51="","No expiry on file",IF(G51<TODAY(),"EXPIRED",IF(G51-TODAY()<=30,"Expiring soon","OK")))) | K51: =IF(A51="","",SUMIFS('Job Costs'!$I$5:$I$1004,'Job Costs'!$E$5:$E$1004,A51,'Job Costs'!$A$5:$A$1004,">="&DATE(Settings!$B$14,1,1),'Job Costs'!$A$5:$A$1004,"<="&DATE(Settings!$B$14,12,31))) | L51: =IF(A51="","",SUMIFS('Job Costs'!$I$5:$I$1004,'Job Costs'!$E$5:$E$1004,A51,'Job Costs'!$J$5:$J$1004,"No")) | M51: =IF(A51="","",IF(AND(J51="Yes",K51>=600),"Review for 1099","")) | N51: =IF(A51="","",IF(COUNTIF('Vendors & Crew'!$A$41:$A$140,A51)>1,"Duplicate vendor",""))
H52: =IF(A52="","",IF(G52="","No expiry on file",IF(G52<TODAY(),"EXPIRED",IF(G52-TODAY()<=30,"Expiring soon","OK")))) | K52: =IF(A52="","",SUMIFS('Job Costs'!$I$5:$I$1004,'Job Costs'!$E$5:$E$1004,A52,'Job Costs'!$A$5:$A$1004,">="&DATE(Settings!$B$14,1,1),'Job Costs'!$A$5:$A$1004,"<="&DATE(Settings!$B$14,12,31))) | L52: =IF(A52="","",SUMIFS('Job Costs'!$I$5:$I$1004,'Job Costs'!$E$5:$E$1004,A52,'Job Costs'!$J$5:$J$1004,"No")) | M52: =IF(A52="","",IF(AND(J52="Yes",K52>=600),"Review for 1099","")) | N52: =IF(A52="","",IF(COUNTIF('Vendors & Crew'!$A$41:$A$140,A52)>1,"Duplicate vendor",""))
... H140: =IF(A140="","",IF(G140="","No expiry on file",IF(G140<TODAY(),"EXPIRED",IF(G140-TODAY()<=30,"Expiring soon","OK")))) | K140: =IF(A140="","",SUMIFS('Job Costs'!$I$5:$I$1004,'Job Costs'!$E$5:$E$1004,A140,'Job Costs'!$A$5:$A$1004,">="&DATE(Settings!$B$14,1,1),'Job Costs'!$A$5:$A$1004,"<="&DATE(Settings!$B$14,12,31))) | L140: =IF(A140="","",SUMIFS('Job Costs'!$I$5:$I$1004,'Job Costs'!$E$5:$E$1004,A140,'Job Costs'!$J$5:$J$1004,"No")) | M140: =IF(A140="","",IF(AND(J140="Yes",K140>=600),"Review for 1099","")) | N140: =IF(A140="","",IF(COUNTIF('Vendors & Crew'!$A$41:$A$140,A140)>1,"Duplicate vendor",""))
A142: 1099 flag is informational only (US vendors paid $600+ in the year and marked eligible). Confirm requirements with your tax professional.

Sheet Cost Library
A1: Cost Library (price book)
A2: Save the items you estimate repeatedly. On the Estimate sheet, pick a Library Item and the unit and unit cost fill in unless you type your own.
A4: Item | B4: Cost Code | C4: Unit | D4: Unit Cost | E4: Category | F4: Used in estimates | G4: Notes
E5: =IF(B5="","",IFERROR(VLOOKUP(B5,Settings!$E$5:$G$28,3,FALSE),"Other")) | F5: =IF(A5="","",COUNTIF(Estimate!$C$5:$C$404,A5))
E6: =IF(B6="","",IFERROR(VLOOKUP(B6,Settings!$E$5:$G$28,3,FALSE),"Other")) | F6: =IF(A6="","",COUNTIF(Estimate!$C$5:$C$404,A6))
E7: =IF(B7="","",IFERROR(VLOOKUP(B7,Settings!$E$5:$G$28,3,FALSE),"Other")) | F7: =IF(A7="","",COUNTIF(Estimate!$C$5:$C$404,A7))
E8: =IF(B8="","",IFERROR(VLOOKUP(B8,Settings!$E$5:$G$28,3,FALSE),"Other")) | F8: =IF(A8="","",COUNTIF(Estimate!$C$5:$C$404,A8))
E9: =IF(B9="","",IFERROR(VLOOKUP(B9,Settings!$E$5:$G$28,3,FALSE),"Other")) | F9: =IF(A9="","",COUNTIF(Estimate!$C$5:$C$404,A9))
E10: =IF(B10="","",IFERROR(VLOOKUP(B10,Settings!$E$5:$G$28,3,FALSE),"Other")) | F10: =IF(A10="","",COUNTIF(Estimate!$C$5:$C$404,A10))
E11: =IF(B11="","",IFERROR(VLOOKUP(B11,Settings!$E$5:$G$28,3,FALSE),"Other")) | F11: =IF(A11="","",COUNTIF(Estimate!$C$5:$C$404,A11))
E12: =IF(B12="","",IFERROR(VLOOKUP(B12,Settings!$E$5:$G$28,3,FALSE),"Other")) | F12: =IF(A12="","",COUNTIF(Estimate!$C$5:$C$404,A12))
E13: =IF(B13="","",IFERROR(VLOOKUP(B13,Settings!$E$5:$G$28,3,FALSE),"Other")) | F13: =IF(A13="","",COUNTIF(Estimate!$C$5:$C$404,A13))
E14: =IF(B14="","",IFERROR(VLOOKUP(B14,Settings!$E$5:$G$28,3,FALSE),"Other")) | F14: =IF(A14="","",COUNTIF(Estimate!$C$5:$C$404,A14))
E15: =IF(B15="","",IFERROR(VLOOKUP(B15,Settings!$E$5:$G$28,3,FALSE),"Other")) | F15: =IF(A15="","",COUNTIF(Estimate!$C$5:$C$404,A15))
E16: =IF(B16="","",IFERROR(VLOOKUP(B16,Settings!$E$5:$G$28,3,FALSE),"Other")) | F16: =IF(A16="","",COUNTIF(Estimate!$C$5:$C$404,A16))
... E204: =IF(B204="","",IFERROR(VLOOKUP(B204,Settings!$E$5:$G$28,3,FALSE),"Other")) | F204: =IF(A204="","",COUNTIF(Estimate!$C$5:$C$404,A204))

Sheet Jobs
A1: Jobs
A2: One row per job. Costs, hours, invoices and payments flow in from the other sheets. Contract Value is optional: leave blank to use the Estimate Price.
A3: ="Suggested next Job ID: J-"&(1000+COUNTA(A5:A44)+1)
A4: Job ID | B4: Client | C4: Job address / description | D4: Status | E4: Start date | F4: Target end | G4: % Complete (manual) | H4: Estimate Price | I4: Contract Value (signed) | J4: Approved Change Orders | K4: Revised Contract | L4: Estimated Cost | M4: Actual Cost to Date | N4: Cost Variance | O4: % of Budget Used | P4: Labor Hours | Q4: Invoiced | R4: Collected | S4: Balance Due | T4: Projected Gross Profit | U4: Projected Margin % | V4: Estimated Margin % | W4: Days to Target | X4: Check | Y4: Notes
H5: =IF($A5="","",SUMIFS(Estimate!$M$5:$M$404,Estimate!$A$5:$A$404,$A5)) | J5: =IF($A5="","",SUMIFS('Change Orders'!$H$5:$H$104,'Change Orders'!$B$5:$B$104,$A5,'Change Orders'!$E$5:$E$104,"Approved")) | K5: =IF($A5="","",IF(I5="",H5,I5)+J5) | L5: =IF($A5="","",SUMIFS(Estimate!$K$5:$K$404,Estimate!$A$5:$A$404,$A5)+SUMIFS('Change Orders'!$G$5:$G$104,'Change Orders'!$B$5:$B$104,$A5,'Change Orders'!$E$5:$E$104,"Approved")) | M5: =IF($A5="","",SUMIFS('Job Costs'!$I$5:$I$1004,'Job Costs'!$B$5:$B$1004,$A5)+SUMIFS(Timesheet!$H$5:$H$1004,Timesheet!$C$5:$C$1004,$A5)+SUMIFS(Mileage!$I$5:$I$304,Mileage!$B$5:$B$304,$A5)) | N5: =IF($A5="","",L5-M5) | O5: =IF($A5="","",IF(L5=0,0,M5/L5)) | P5: =IF($A5="","",SUMIFS(Timesheet!$E$5:$E$1004,Timesheet!$C$5:$C$1004,$A5)+SUMIFS('Job Costs'!$G$5:$G$1004,'Job Costs'!$B$5:$B$1004,$A5,'Job Costs'!$D$5:$D$1004,"Labor")) | Q5: =IF($A5="","",SUMIFS(Invoices!$E$5:$E$204,Invoices!$B$5:$B$204,$A5)) | R5: =IF($A5="","",SUMIFS(Payments!$D$5:$D$304,Payments!$B$5:$B$304,$A5)) | S5: =IF($A5="","",Q5-R5) | T5: =IF($A5="","",K5-MAX(L5,M5)) | U5: =IF($A5="","",IF(K5=0,0,T5/K5)) | V5: =IF($A5="","",IF(K5=0,0,(K5-L5)/K5)) | W5: =IF(OR($A5="",F5="",D5="Complete",D5="Closed",D5="Lost"),"",F5-TODAY()) | X5: =IF($A5="","",IF(COUNTIF(Jobs!$A$5:$A$44,$A5)>1,"Duplicate Job ID",IF(AND(B5<>"",COUNTIF(Clients!$A$5:$A$104,B5)=0),"Client not in Clients sheet",IF(D5="","Missing status",IF(AND(OR(D5="Approved",D5="In Progress"),H5=0,I5=""),"Active job with no estimate or contract value","")))))
H6: =IF($A6="","",SUMIFS(Estimate!$M$5:$M$404,Estimate!$A$5:$A$404,$A6)) | J6: =IF($A6="","",SUMIFS('Change Orders'!$H$5:$H$104,'Change Orders'!$B$5:$B$104,$A6,'Change Orders'!$E$5:$E$104,"Approved")) | K6: =IF($A6="","",IF(I6="",H6,I6)+J6) | L6: =IF($A6="","",SUMIFS(Estimate!$K$5:$K$404,Estimate!$A$5:$A$404,$A6)+SUMIFS('Change Orders'!$G$5:$G$104,'Change Orders'!$B$5:$B$104,$A6,'Change Orders'!$E$5:$E$104,"Approved")) | M6: =IF($A6="","",SUMIFS('Job Costs'!$I$5:$I$1004,'Job Costs'!$B$5:$B$1004,$A6)+SUMIFS(Timesheet!$H$5:$H$1004,Timesheet!$C$5:$C$1004,$A6)+SUMIFS(Mileage!$I$5:$I$304,Mileage!$B$5:$B$304,$A6)) | N6: =IF($A6="","",L6-M6) | O6: =IF($A6="","",IF(L6=0,0,M6/L6)) | P6: =IF($A6="","",SUMIFS(Timesheet!$E$5:$E$1004,Timesheet!$C$5:$C$1004,$A6)+SUMIFS('Job Costs'!$G$5:$G$1004,'Job Costs'!$B$5:$B$1004,$A6,'Job Costs'!$D$5:$D$1004,"Labor")) | Q6: =IF($A6="","",SUMIFS(Invoices!$E$5:$E$204,Invoices!$B$5:$B$204,$A6)) | R6: =IF($A6="","",SUMIFS(Payments!$D$5:$D$304,Payments!$B$5:$B$304,$A6)) | S6: =IF($A6="","",Q6-R6) | T6: =IF($A6="","",K6-MAX(L6,M6)) | U6: =IF($A6="","",IF(K6=0,0,T6/K6)) | V6: =IF($A6="","",IF(K6=0,0,(K6-L6)/K6)) | W6: =IF(OR($A6="",F6="",D6="Complete",D6="Closed",D6="Lost"),"",F6-TODAY()) | X6: =IF($A6="","",IF(COUNTIF(Jobs!$A$5:$A$44,$A6)>1,"Duplicate Job ID",IF(AND(B6<>"",COUNTIF(Clients!$A$5:$A$104,B6)=0),"Client not in Clients sheet",IF(D6="","Missing status",IF(AND(OR(D6="Approved",D6="In Progress"),H6=0,I6=""),"Active job with no estimate or contract value","")))))
H7: =IF($A7="","",SUMIFS(Estimate!$M$5:$M$404,Estimate!$A$5:$A$404,$A7)) | J7: =IF($A7="","",SUMIFS('Change Orders'!$H$5:$H$104,'Change Orders'!$B$5:$B$104,$A7,'Change Orders'!$E$5:$E$104,"Approved")) | K7: =IF($A7="","",IF(I7="",H7,I7)+J7) | L7: =IF($A7="","",SUMIFS(Estimate!$K$5:$K$404,Estimate!$A$5:$A$404,$A7)+SUMIFS('Change Orders'!$G$5:$G$104,'Change Orders'!$B$5:$B$104,$A7,'Change Orders'!$E$5:$E$104,"Approved")) | M7: =IF($A7="","",SUMIFS('Job Costs'!$I$5:$I$1004,'Job Costs'!$B$5:$B$1004,$A7)+SUMIFS(Timesheet!$H$5:$H$1004,Timesheet!$C$5:$C$1004,$A7)+SUMIFS(Mileage!$I$5:$I$304,Mileage!$B$5:$B$304,$A7)) | N7: =IF($A7="","",L7-M7) | O7: =IF($A7="","",IF(L7=0,0,M7/L7)) | P7: =IF($A7="","",SUMIFS(Timesheet!$E$5:$E$1004,Timesheet!$C$5:$C$1004,$A7)+SUMIFS('Job Costs'!$G$5:$G$1004,'Job Costs'!$B$5:$B$1004,$A7,'Job Costs'!$D$5:$D$1004,"Labor")) | Q7: =IF($A7="","",SUMIFS(Invoices!$E$5:$E$204,Invoices!$B$5:$B$204,$A7)) | R7: =IF($A7="","",SUMIFS(Payments!$D$5:$D$304,Payments!$B$5:$B$304,$A7)) | S7: =IF($A7="","",Q7-R7) | T7: =IF($A7="","",K7-MAX(L7,M7)) | U7: =IF($A7="","",IF(K7=0,0,T7/K7)) | V7: =IF($A7="","",IF(K7=0,0,(K7-L7)/K7)) | W7: =IF(OR($A7="",F7="",D7="Complete",D7="Closed",D7="Lost"),"",F7-TODAY()) | X7: =IF($A7="","",IF(COUNTIF(Jobs!$A$5:$A$44,$A7)>1,"Duplicate Job ID",IF(AND(B7<>"",COUNTIF(Clients!$A$5:$A$104,B7)=0),"Client not in Clients sheet",IF(D7="","Missing status",IF(AND(OR(D7="Approved",D7="In Progress"),H7=0,I7=""),"Active job with no estimate or contract value","")))))
H8: =IF($A8="","",SUMIFS(Estimate!$M$5:$M$404,Estimate!$A$5:$A$404,$A8)) | J8: =IF($A8="","",SUMIFS('Change Orders'!$H$5:$H$104,'Change Orders'!$B$5:$B$104,$A8,'Change Orders'!$E$5:$E$104,"Approved")) | K8: =IF($A8="","",IF(I8="",H8,I8)+J8) | L8: =IF($A8="","",SUMIFS(Estimate!$K$5:$K$404,Estimate!$A$5:$A$404,$A8)+SUMIFS('Change Orders'!$G$5:$G$104,'Change Orders'!$B$5:$B$104,$A8,'Change Orders'!$E$5:$E$104,"Approved")) | M8: =IF($A8="","",SUMIFS('Job Costs'!$I$5:$I$1004,'Job Costs'!$B$5:$B$1004,$A8)+SUMIFS(Timesheet!$H$5:$H$1004,Timesheet!$C$5:$C$1004,$A8)+SUMIFS(Mileage!$I$5:$I$304,Mileage!$B$5:$B$304,$A8)) | N8: =IF($A8="","",L8-M8) | O8: =IF($A8="","",IF(L8=0,0,M8/L8)) | P8: =IF($A8="","",SUMIFS(Timesheet!$E$5:$E$1004,Timesheet!$C$5:$C$1004,$A8)+SUMIFS('Job Costs'!$G$5:$G$1004,'Job Costs'!$B$5:$B$1004,$A8,'Job Costs'!$D$5:$D$1004,"Labor")) | Q8: =IF($A8="","",SUMIFS(Invoices!$E$5:$E$204,Invoices!$B$5:$B$204,$A8)) | R8: =IF($A8="","",SUMIFS(Payments!$D$5:$D$304,Payments!$B$5:$B$304,$A8)) | S8: =IF($A8="","",Q8-R8) | T8: =IF($A8="","",K8-MAX(L8,M8)) | U8: =IF($A8="","",IF(K8=0,0,T8/K8)) | V8: =IF($A8="","",IF(K8=0,0,(K8-L8)/K8)) | W8: =IF(OR($A8="",F8="",D8="Complete",D8="Closed",D8="Lost"),"",F8-TODAY()) | X8: =IF($A8="","",IF(COUNTIF(Jobs!$A$5:$A$44,$A8)>1,"Duplicate Job ID",IF(AND(B8<>"",COUNTIF(Clients!$A$5:$A$104,B8)=0),"Client not in Clients sheet",IF(D8="","Missing status",IF(AND(OR(D8="Approved",D8="In Progress"),H8=0,I8=""),"Active job with no estimate or contract value","")))))
H9: =IF($A9="","",SUMIFS(Estimate!$M$5:$M$404,Estimate!$A$5:$A$404,$A9)) | J9: =IF($A9="","",SUMIFS('Change Orders'!$H$5:$H$104,'Change Orders'!$B$5:$B$104,$A9,'Change Orders'!$E$5:$E$104,"Approved")) | K9: =IF($A9="","",IF(I9="",H9,I9)+J9) | L9: =IF($A9="","",SUMIFS(Estimate!$K$5:$K$404,Estimate!$A$5:$A$404,$A9)+SUMIFS('Change Orders'!$G$5:$G$104,'Change Orders'!$B$5:$B$104,$A9,'Change Orders'!$E$5:$E$104,"Approved")) | M9: =IF($A9="","",SUMIFS('Job Costs'!$I$5:$I$1004,'Job Costs'!$B$5:$B$1004,$A9)+SUMIFS(Timesheet!$H$5:$H$1004,Timesheet!$C$5:$C$1004,$A9)+SUMIFS(Mileage!$I$5:$I$304,Mileage!$B$5:$B$304,$A9)) | N9: =IF($A9="","",L9-M9) | O9: =IF($A9="","",IF(L9=0,0,M9/L9)) | P9: =IF($A9="","",SUMIFS(Timesheet!$E$5:$E$1004,Timesheet!$C$5:$C$1004,$A9)+SUMIFS('Job Costs'!$G$5:$G$1004,'Job Costs'!$B$5:$B$1004,$A9,'Job Costs'!$D$5:$D$1004,"Labor")) | Q9: =IF($A9="","",SUMIFS(Invoices!$E$5:$E$204,Invoices!$B$5:$B$204,$A9)) | R9: =IF($A9="","",SUMIFS(Payments!$D$5:$D$304,Payments!$B$5:$B$304,$A9)) | S9: =IF($A9="","",Q9-R9) | T9: =IF($A9="","",K9-MAX(L9,M9)) | U9: =IF($A9="","",IF(K9=0,0,T9/K9)) | V9: =IF($A9="","",IF(K9=0,0,(K9-L9)/K9)) | W9: =IF(OR($A9="",F9="",D9="Complete",D9="Closed",D9="Lost"),"",F9-TODAY()) | X9: =IF($A9="","",IF(COUNTIF(Jobs!$A$5:$A$44,$A9)>1,"Duplicate Job ID",IF(AND(B9<>"",COUNTIF(Clients!$A$5:$A$104,B9)=0),"Client not in Clients sheet",IF(D9="","Missing status",IF(AND(OR(D9="Approved",D9="In Progress"),H9=0,I9=""),"Active job with no estimate or contract value","")))))
H10: =IF($A10="","",SUMIFS(Estimate!$M$5:$M$404,Estimate!$A$5:$A$404,$A10)) | J10: =IF($A10="","",SUMIFS('Change Orders'!$H$5:$H$104,'Change Orders'!$B$5:$B$104,$A10,'Change Orders'!$E$5:$E$104,"Approved")) | K10: =IF($A10="","",IF(I10="",H10,I10)+J10) | L10: =IF($A10="","",SUMIFS(Estimate!$K$5:$K$404,Estimate!$A$5:$A$404,$A10)+SUMIFS('Change Orders'!$G$5:$G$104,'Change Orders'!$B$5:$B$104,$A10,'Change Orders'!$E$5:$E$104,"Approved")) | M10: =IF($A10="","",SUMIFS('Job Costs'!$I$5:$I$1004,'Job Costs'!$B$5:$B$1004,$A10)+SUMIFS(Timesheet!$H$5:$H$1004,Timesheet!$C$5:$C$1004,$A10)+SUMIFS(Mileage!$I$5:$I$304,Mileage!$B$5:$B$304,$A10)) | N10: =IF($A10="","",L10-M10) | O10: =IF($A10="","",IF(L10=0,0,M10/L10)) | P10: =IF($A10="","",SUMIFS(Timesheet!$E$5:$E$1004,Timesheet!$C$5:$C$1004,$A10)+SUMIFS('Job Costs'!$G$5:$G$1004,'Job Costs'!$B$5:$B$1004,$A10,'Job Costs'!$D$5:$D$1004,"Labor")) | Q10: =IF($A10="","",SUMIFS(Invoices!$E$5:$E$204,Invoices!$B$5:$B$204,$A10)) | R10: =IF($A10="","",SUMIFS(Payments!$D$5:$D$304,Payments!$B$5:$B$304,$A10)) | S10: =IF($A10="","",Q10-R10) | T10: =IF($A10="","",K10-MAX(L10,M10)) | U10: =IF($A10="","",IF(K10=0,0,T10/K10)) | V10: =IF($A10="","",IF(K10=0,0,(K10-L10)/K10)) | W10: =IF(OR($A10="",F10="",D10="Complete",D10="Closed",D10="Lost"),"",F10-TODAY()) | X10: =IF($A10="","",IF(COUNTIF(Jobs!$A$5:$A$44,$A10)>1,"Duplicate Job ID",IF(AND(B10<>"",COUNTIF(Clients!$A$5:$A$104,B10)=0),"Client not in Clients sheet",IF(D10="","Missing status",IF(AND(OR(D10="Approved",D10="In Progress"),H10=0,I10=""),"Active job with no estimate or contract value","")))))
H11: =IF($A11="","",SUMIFS(Estimate!$M$5:$M$404,Estimate!$A$5:$A$404,$A11)) | J11: =IF($A11="","",SUMIFS('Change Orders'!$H$5:$H$104,'Change Orders'!$B$5:$B$104,$A11,'Change Orders'!$E$5:$E$104,"Approved")) | K11: =IF($A11="","",IF(I11="",H11,I11)+J11) | L11: =IF($A11="","",SUMIFS(Estimate!$K$5:$K$404,Estimate!$A$5:$A$404,$A11)+SUMIFS('Change Orders'!$G$5:$G$104,'Change Orders'!$B$5:$B$104,$A11,'Change Orders'!$E$5:$E$104,"Approved")) | M11: =IF($A11="","",SUMIFS('Job Costs'!$I$5:$I$1004,'Job Costs'!$B$5:$B$1004,$A11)+SUMIFS(Timesheet!$H$5:$H$1004,Timesheet!$C$5:$C$1004,$A11)+SUMIFS(Mileage!$I$5:$I$304,Mileage!$B$5:$B$304,$A11)) | N11: =IF($A11="","",L11-M11) | O11: =IF($A11="","",IF(L11=0,0,M11/L11)) | P11: =IF($A11="","",SUMIFS(Timesheet!$E$5:$E$1004,Timesheet!$C$5:$C$1004,$A11)+SUMIFS('Job Costs'!$G$5:$G$1004,'Job Costs'!$B$5:$B$1004,$A11,'Job Costs'!$D$5:$D$1004,"Labor")) | Q11: =IF($A11="","",SUMIFS(Invoices!$E$5:$E$204,Invoices!$B$5:$B$204,$A11)) | R11: =IF($A11="","",SUMIFS(Payments!$D$5:$D$304,Payments!$B$5:$B$304,$A11)) | S11: =IF($A11="","",Q11-R11) | T11: =IF($A11="","",K11-MAX(L11,M11)) | U11: =IF($A11="","",IF(K11=0,0,T11/K11)) | V11: =IF($A11="","",IF(K11=0,0,(K11-L11)/K11)) | W11: =IF(OR($A11="",F11="",D11="Complete",D11="Closed",D11="Lost"),"",F11-TODAY()) | X11: =IF($A11="","",IF(COUNTIF(Jobs!$A$5:$A$44,$A11)>1,"Duplicate Job ID",IF(AND(B11<>"",COUNTIF(Clients!$A$5:$A$104,B11)=0),"Client not in Clients sheet",IF(D11="","Missing status",IF(AND(OR(D11="Approved",D11="In Progress"),H11=0,I11=""),"Active job with no estimate or contract value","")))))
H12: =IF($A12="","",SUMIFS(Estimate!$M$5:$M$404,Estimate!$A$5:$A$404,$A12)) | J12: =IF($A12="","",SUMIFS('Change Orders'!$H$5:$H$104,'Change Orders'!$B$5:$B$104,$A12,'Change Orders'!$E$5:$E$104,"Approved")) | K12: =IF($A12="","",IF(I12="",H12,I12)+J12) | L12: =IF($A12="","",SUMIFS(Estimate!$K$5:$K$404,Estimate!$A$5:$A$404,$A12)+SUMIFS('Change Orders'!$G$5:$G$104,'Change Orders'!$B$5:$B$104,$A12,'Change Orders'!$E$5:$E$104,"Approved")) | M12: =IF($A12="","",SUMIFS('Job Costs'!$I$5:$I$1004,'Job Costs'!$B$5:$B$1004,$A12)+SUMIFS(Timesheet!$H$5:$H$1004,Timesheet!$C$5:$C$1004,$A12)+SUMIFS(Mileage!$I$5:$I$304,Mileage!$B$5:$B$304,$A12)) | N12: =IF($A12="","",L12-M12) | O12: =IF($A12="","",IF(L12=0,0,M12/L12)) | P12: =IF($A12="","",SUMIFS(Timesheet!$E$5:$E$1004,Timesheet!$C$5:$C$1004,$A12)+SUMIFS('Job Costs'!$G$5:$G$1004,'Job Costs'!$B$5:$B$1004,$A12,'Job Costs'!$D$5:$D$1004,"Labor")) | Q12: =IF($A12="","",SUMIFS(Invoices!$E$5:$E$204,Invoices!$B$5:$B$204,$A12)) | R12: =IF($A12="","",SUMIFS(Payments!$D$5:$D$304,Payments!$B$5:$B$304,$A12)) | S12: =IF($A12="","",Q12-R12) | T12: =IF($A12="","",K12-MAX(L12,M12)) | U12: =IF($A12="","",IF(K12=0,0,T12/K12)) | V12: =IF($A12="","",IF(K12=0,0,(K12-L12)/K12)) | W12: =IF(OR($A12="",F12="",D12="Complete",D12="Closed",D12="Lost"),"",F12-TODAY()) | X12: =IF($A12="","",IF(COUNTIF(Jobs!$A$5:$A$44,$A12)>1,"Duplicate Job ID",IF(AND(B12<>"",COUNTIF(Clients!$A$5:$A$104,B12)=0),"Client not in Clients sheet",IF(D12="","Missing status",IF(AND(OR(D12="Approved",D12="In Progress"),H12=0,I12=""),"Active job with no estimate or contract value","")))))
H13: =IF($A13="","",SUMIFS(Estimate!$M$5:$M$404,Estimate!$A$5:$A$404,$A13)) | J13: =IF($A13="","",SUMIFS('Change Orders'!$H$5:$H$104,'Change Orders'!$B$5:$B$104,$A13,'Change Orders'!$E$5:$E$104,"Approved")) | K13: =IF($A13="","",IF(I13="",H13,I13)+J13) | L13: =IF($A13="","",SUMIFS(Estimate!$K$5:$K$404,Estimate!$A$5:$A$404,$A13)+SUMIFS('Change Orders'!$G$5:$G$104,'Change Orders'!$B$5:$B$104,$A13,'Change Orders'!$E$5:$E$104,"Approved")) | M13: =IF($A13="","",SUMIFS('Job Costs'!$I$5:$I$1004,'Job Costs'!$B$5:$B$1004,$A13)+SUMIFS(Timesheet!$H$5:$H$1004,Timesheet!$C$5:$C$1004,$A13)+SUMIFS(Mileage!$I$5:$I$304,Mileage!$B$5:$B$304,$A13)) | N13: =IF($A13="","",L13-M13) | O13: =IF($A13="","",IF(L13=0,0,M13/L13)) | P13: =IF($A13="","",SUMIFS(Timesheet!$E$5:$E$1004,Timesheet!$C$5:$C$1004,$A13)+SUMIFS('Job Costs'!$G$5:$G$1004,'Job Costs'!$B$5:$B$1004,$A13,'Job Costs'!$D$5:$D$1004,"Labor")) | Q13: =IF($A13="","",SUMIFS(Invoices!$E$5:$E$204,Invoices!$B$5:$B$204,$A13)) | R13: =IF($A13="","",SUMIFS(Payments!$D$5:$D$304,Payments!$B$5:$B$304,$A13)) | S13: =IF($A13="","",Q13-R13) | T13: =IF($A13="","",K13-MAX(L13,M13)) | U13: =IF($A13="","",IF(K13=0,0,T13/K13)) | V13: =IF($A13="","",IF(K13=0,0,(K13-L13)/K13)) | W13: =IF(OR($A13="",F13="",D13="Complete",D13="Closed",D13="Lost"),"",F13-TODAY()) | X13: =IF($A13="","",IF(COUNTIF(Jobs!$A$5:$A$44,$A13)>1,"Duplicate Job ID",IF(AND(B13<>"",COUNTIF(Clients!$A$5:$A$104,B13)=0),"Client not in Clients sheet",IF(D13="","Missing status",IF(AND(OR(D13="Approved",D13="In Progress"),H13=0,I13=""),"Active job with no estimate or contract value","")))))
H14: =IF($A14="","",SUMIFS(Estimate!$M$5:$M$404,Estimate!$A$5:$A$404,$A14)) | J14: =IF($A14="","",SUMIFS('Change Orders'!$H$5:$H$104,'Change Orders'!$B$5:$B$104,$A14,'Change Orders'!$E$5:$E$104,"Approved")) | K14: =IF($A14="","",IF(I14="",H14,I14)+J14) | L14: =IF($A14="","",SUMIFS(Estimate!$K$5:$K$404,Estimate!$A$5:$A$404,$A14)+SUMIFS('Change Orders'!$G$5:$G$104,'Change Orders'!$B$5:$B$104,$A14,'Change Orders'!$E$5:$E$104,"Approved")) | M14: =IF($A14="","",SUMIFS('Job Costs'!$I$5:$I$1004,'Job Costs'!$B$5:$B$1004,$A14)+SUMIFS(Timesheet!$H$5:$H$1004,Timesheet!$C$5:$C$1004,$A14)+SUMIFS(Mileage!$I$5:$I$304,Mileage!$B$5:$B$304,$A14)) | N14: =IF($A14="","",L14-M14) | O14: =IF($A14="","",IF(L14=0,0,M14/L14)) | P14: =IF($A14="","",SUMIFS(Timesheet!$E$5:$E$1004,Timesheet!$C$5:$C$1004,$A14)+SUMIFS('Job Costs'!$G$5:$G$1004,'Job Costs'!$B$5:$B$1004,$A14,'Job Costs'!$D$5:$D$1004,"Labor")) | Q14: =IF($A14="","",SUMIFS(Invoices!$E$5:$E$204,Invoices!$B$5:$B$204,$A14)) | R14: =IF($A14="","",SUMIFS(Payments!$D$5:$D$304,Payments!$B$5:$B$304,$A14)) | S14: =IF($A14="","",Q14-R14) | T14: =IF($A14="","",K14-MAX(L14,M14)) | U14: =IF($A14="","",IF(K14=0,0,T14/K14)) | V14: =IF($A14="","",IF(K14=0,0,(K14-L14)/K14)) | W14: =IF(OR($A14="",F14="",D14="Complete",D14="Closed",D14="Lost"),"",F14-TODAY()) | X14: =IF($A14="","",IF(COUNTIF(Jobs!$A$5:$A$44,$A14)>1,"Duplicate Job ID",IF(AND(B14<>"",COUNTIF(Clients!$A$5:$A$104,B14)=0),"Client not in Clients sheet",IF(D14="","Missing status",IF(AND(OR(D14="Approved",D14="In Progress"),H14=0,I14=""),"Active job with no estimate or contract value","")))))
